Traceback (most recent call last):
  File "/home/rchap/anaconda3/envs/ivar-freyja/lib/python3.10/functools.py", line 952, in __set_name__
    def __set_name__(self, owner, name):
KeyboardInterrupt

The above exception was the direct cause of the following exception:

Traceback (most recent call last):
  File "/home/rchap/anaconda3/envs/ivar-freyja/bin/freyja", line 6, in <module>
    from freyja._cli import cli
  File "/home/rchap/anaconda3/envs/ivar-freyja/lib/python3.10/site-packages/freyja/_cli.py", line 2, in <module>
    import pandas as pd
  File "/home/rchap/anaconda3/envs/ivar-freyja/lib/python3.10/site-packages/pandas/__init__.py", line 11, in <module>
    __import__(dependency)
  File "/home/rchap/anaconda3/envs/ivar-freyja/lib/python3.10/site-packages/numpy/__init__.py", line 144, in <module>
    from . import core
  File "/home/rchap/anaconda3/envs/ivar-freyja/lib/python3.10/site-packages/numpy/core/__init__.py", line 100, in <module>
    from . import _add_newdocs_scalars
  File "/home/rchap/anaconda3/envs/ivar-freyja/lib/python3.10/site-packages/numpy/core/_add_newdocs_scalars.py", line 9, in <module>
    import platform
  File "/home/rchap/anaconda3/envs/ivar-freyja/lib/python3.10/platform.py", line 772, in <module>
    class uname_result(
RuntimeError: Error calling __set_name__ on 'cached_property' instance 'processor' in 'uname_result'
